<?xml version='1.0'?>

<robot name="my_robot" xmlns:xacro="http://www.ros.org/wiki/xacro">

  <xacro:include filename="$(find my_robot)/urdf/my_robot.gazebo" />
  
  <material name="blue">
    <color rgba="0 0.3 0.8 1"/>
  </material>
    
  <material name="green">
     <color rgba="0 0.75 0.3 1"/>
  </material>
  
  <material name="black">
     <color rgba="0. 0 0. 1"/>
  </material>

  <link name="robot_footprint"></link>

  <joint name="robot_footprint_joint" type="fixed">
    <origin xyz="0 0 0" rpy="0 0 0" />
    <parent link="robot_footprint"/>
    <child link="chassis" />
  </joint>

  <link name='chassis'>
    <pose>0 0 0.1 0 0 0</pose>

    <inertial>
      <mass value="15.0"/>
      <origin xyz="0.0 0 .1" rpy=" 0 0 0"/>
      <inertia
          ixx="0.1" ixy="0" ixz="0"
          iyy="0.1" iyz="0"
          izz="0.1"
      />
    </inertial>

    // HEAD
    <collision>
      <origin xyz="0 0 0.15" rpy=" 0 0 0"/> 
      <geometry>
        <sphere radius=".2"/>
      </geometry>
    </collision>

    <visual>
      <origin xyz="0 0 0.15" rpy=" 0 0 0"/>
      <geometry>
        <sphere radius=".2"/>
      </geometry>
      <material name="blue"/>
    </visual>

    <collision name='chasis_collision'>
      <origin xyz="0 0 0" rpy=" 0 0 0"/> 
      <geometry>
        <cylinder radius=".2" length=".3"/>
      </geometry>
    </collision>

    <visual name='chassis_visual'>
      <origin xyz="0 0 0" rpy=" 0 0 0"/>
      <geometry>
        <cylinder radius=".2" length=".3"/>
      </geometry>
      <material name="blue"/>
    </visual>


    <collision name='back_caster_collision'>
      <origin xyz="-0.15 0 -0.15" rpy=" 0 0 0"/>
      <geometry>
        <sphere radius="0.0499"/>
      </geometry>
    </collision>

    <visual name='back_caster_visual'>
      <origin xyz="-0.15 0 -0.15" rpy=" 0 0 0"/>
      <geometry>
        <sphere radius="0.05"/>
      </geometry>
      <material name="fuchsia"/>
    </visual>

    <collision name='front_caster_collision'>
      <origin xyz="0.15 0 -0.15" rpy=" 0 0 0"/>
      <geometry>
        <sphere radius="0.0499"/>
      </geometry>
    </collision>

    <visual name='front_caster_visual'>
      <origin xyz="0.15 0 -0.15" rpy=" 0 0 0"/>
      <geometry>
        <sphere radius="0.05"/>
      </geometry>
      <material name="fuchsia"/>
    </visual>
  </link>

  <link name ='right_wheel'>

   <inertial>
     <mass value="5.0"/>
     <origin xyz="0 0 0" rpy="0 1.5707 1.5707"/>
     <inertia
         ixx="0.1" ixy="0" ixz="0"
         iyy="0.1" iyz="0"
         izz="0.1"
     />
   </inertial>

    <visual name="right_wheel_visual">
      <origin xyz="0 0 0" rpy="0 1.5707 1.5707"/>
      <geometry>
        <cylinder radius="0.125" length="0.05"/>
      </geometry>
      <material name="green"/>
    </visual>

    <collision name="right_wheel_collision">
      <origin xyz="0 0 0" rpy="0 1.5707 1.5707"/>
      <geometry>
        <cylinder radius="0.125" length="0.05"/>
      </geometry>
    </collision>

  </link>

  <link name ='left_wheel'>

   <inertial>
     <mass value="5.0"/>
     <origin xyz="0 0 0" rpy="0 1.5707 1.5707"/>
     <inertia
         ixx="0.1" ixy="0" ixz="0"
         iyy="0.1" iyz="0"
         izz="0.1"
     />
   </inertial>

    <visual name="left_wheel_visual">
      <origin xyz="0 0 0" rpy="0 1.5707 1.5707"/>
      <geometry>
        <cylinder radius="0.125" length="0.05"/>
      </geometry>
      <material name="green"/>
    </visual>

    <collision name="left_wheel_collision">
      <origin xyz="0 0 0" rpy="0 1.5707 1.5707"/>
      <geometry>
        <cylinder radius="0.125" length="0.05"/>
      </geometry>
    </collision>

  </link>

  <joint type="continuous" name="right_wheel_hinge">
    <origin xyz="0 -0.225 -0.075" rpy="0 0 0"/>
    <child link="right_wheel"/>
    <parent link="chassis"/>
    <axis xyz="0 1 0" rpy="0 0 0"/>
    <limit effort="10000" velocity="1000"/>
    <dynamics damping="1.0" friction="1.0"/>
  </joint>

  <joint type="continuous" name="left_wheel_hinge">
    <origin xyz="0 0.225 -0.075" rpy="0 0 0"/>
    <child link="left_wheel"/>
    <parent link="chassis"/>
    <axis xyz="0 1 0" rpy="0 0 0"/>
    <limit effort="10000" velocity="1000"/>
    <dynamics damping="1.0" friction="1.0"/>
  </joint>

  <link name ='camera'>

   <inertial>
     <mass value="0.1"/>
     <origin xyz="0 0 0" rpy="0 0 0"/>
     <inertia
         ixx="1e-6" ixy="0" ixz="0"
         iyy="1e-6" iyz="0"
         izz="1e-6"
     />
   </inertial>

    <visual name="camera_visual">
      <origin xyz="0 0 0" rpy="0 0 0"/>
      <geometry>
        <box size="0.05 0.05 0.05"/>
      </geometry>
      <material name="black"/>
    </visual>

    <collision name="camera_collision">
      <origin xyz="0 0 0" rpy="0 0 0"/>
      <geometry>
        <box size="0.05 0.05 0.05"/>
      </geometry>
    </collision>

  </link>

  <joint type="fixed" name="camera_joint">
    <origin xyz="0.2 0. 0.1" rpy="0 0 0"/>
    <child link="camera"/>
    <parent link="chassis"/>
    <axis xyz="0 1 0" rpy="0 0 0"/>
  </joint>

  <link name ='hokuyo'>

   <inertial>
     <mass value="1e-5"/>
     <origin xyz="0 0 0" rpy="0 0 0"/>
     <inertia
         ixx="1e-6" ixy="0" ixz="0"
         iyy="1e-6" iyz="0"
         izz="1e-6"
     />
   </inertial>

    <visual name="hokuyo_visual">
      <origin xyz="0 0 0" rpy="0 0 0"/>
      <geometry>
        <mesh filename="package://my_robot/meshes/hokuyo.dae"/>
      </geometry>
      <material name="black"/>
    </visual>

    <collision name="hokuyo_collision">
      <origin xyz="0 0 0" rpy="0 0 0"/>
      <geometry>
        <box size="0.1 0.1 0.1"/>
      </geometry>
    </collision>

  </link>

  <joint type="fixed" name="hokuyo_joint">
    <origin xyz="0. 0. 0.39" rpy="0 0 0"/>
    <child link="hokuyo"/>
    <parent link="chassis"/>
    <axis xyz="0 1 0" rpy="0 0 0"/>
  </joint>

  <gazebo reference="chassis">
    <visual>
      <material>
        <ambient>0 0.3 0.8 1.0</ambient>
        <diffuse>0 0.3 0.8 1.0</diffuse>
        <specular>0 0.3 0.8 1.0</specular>
        <emissive>0 0.3 0.8 1.0</emissive>
      </material>
    </visual>
  </gazebo>

  <gazebo reference="right_wheel">
    <visual>
      <material>
        <ambient>0 0.75 0.3 1.0</ambient>
        <diffuse>0 0.75 0.3 1.0</diffuse>
        <specular>0 0.75 0.3 1.0</specular>
        <emissive>0 0.75 0.3 1.0</emissive>
      </material>
    </visual>
  </gazebo>

  <gazebo reference="left_wheel">
    <visual>
      <material>
        <ambient>0 0.75 0.3 1.0</ambient>
        <diffuse>0 0.75 0.3 1.0</diffuse>
        <specular>0 0.75 0.3 1.0</specular>
        <emissive>0 0.75 0.3 1.0</emissive>
      </material>
    </visual>
  </gazebo>

  <gazebo reference="camera">
    <visual>
      <material>
        <ambient>0 0 0 1</ambient>
        <diffuse>0 0 0 1</diffuse>
        <specular>0 0 0 1</specular>
        <emissive>0 0 0 1</emissive>
      </material>
    </visual>
  </gazebo>

  <gazebo reference="hokuyo">
    <visual>
      <material>
        <ambient>0 0 0 1</ambient>
        <diffuse>0 0 0 1</diffuse>
        <specular>0 0 0 1</specular>
        <emissive>0 0 0 1</emissive>
      </material>
    </visual>
  </gazebo>

</robot>
